Workbook

Sheet Lesehilfe
A1: Ergebnisse der Modellbetrachtung | B1: Begleitmappe zu Abschnitt 6.3 der Masterarbeit
A3: Was diese Mappe enthält | B3: Alle Ergebnisse des ereignisdiskreten Ablaufmodells zur Skalierbarkeit der Satellitenfertigung. Die Zahlen stammen aus einem Lauf des Skripts simulation_satellitenfertigung.py und sind durch feste Zufallsstartwerte reproduzierbar.
A5: Aufbau
A6: Kernzahlen | B6: Die Werte, auf die sich Abschnitt 6.3.4 stützt, nach Befund gruppiert. Jede Zahl verweist auf die Zelle im jeweiligen Experimentblatt.
A7: Parameter | B7: Ausprägungen der Modellgrößen und der Ausgangsvergleich.
A8: E1 bis E4 | B8: Die vier Experimente mit allen gerechneten Konfigurationen.
A9: Sensitivität | B9: Prüfung der Befunde bei veränderten Annahmen.
A10: Verifikation | B10: Grenzwerttests zur Prüfung der Modelllogik.
A12: Ergebnisgrößen
A13: Programmdauer | B13: Zeitpunkt, zu dem der letzte der 180 Satelliten die Prüfung abgeschlossen hat.
A14: Konfidenzintervall ± | B14: Halbe Breite des 95-%-Konfidenzintervalls über 30 Läufe. Unterschiede, die kleiner sind, gelten als zufällig.
A15: Ausbringungsrate | B15: Über jeweils 20 fertiggestellte Satelliten gleitend bestimmt, angegeben ist der Endwert am Programmende.
A16: Hochlaufdauer | B16: Zeitpunkt, ab dem die gleitende Ausbringungsrate erstmals 95 % ihres Endwerts erreicht.
A17: Auslastung der Prüfung | B17: Anteil der Programmdauer, in dem die Prüfstationen belegt sind.
A18: Fehlteile je Satellit | B18: Mittlere Zahl fehlender Zukaufteile je Satellit, steigt mit sinkender Fertigungstiefe.
A20: Abkürzungen
A21: ZE | B21: Normierte Zeiteinheit. Die Werte sind untereinander vergleichbar, aber keine realen Minuten oder Stunden.
A22: K | B22: Anzahl der Prüfstationen, die alle Linien gemeinsam nutzen.
A23: v | B23: Wechselwahrscheinlichkeit, also wie häufig sich ein Satellit vom zuvor auf derselben Linie gefertigten unterscheidet.
A24: r | B24: Anpassungsanteil je Station bei einem Variantenwechsel, bezogen auf die nominale Stationszeit. Ein höherer Standardisierungsgrad bedeutet ein kleineres r.
A25: k_auto | B25: Zeitfaktor der Automatisierung auf die reguläre Bearbeitungszeit. Der Wert 1,0 entspricht keinem Vorteil.
A26: f | B26: Fertigungstiefe, also der Anteil des intern gefertigten Arbeitsinhalts.
A27: 1 × 30 bis 15 × 2 | B27: Produktionsorganisation als Linien mal Stationen je Linie. In allen Fällen sind es zusammen 30 Stationsplätze.
A29: Rahmen des Modells | B29: 180 Satelliten je Programm, 30 Stationsplätze, keine Zwischenpuffer, gemeinsame Prüfung mit im Mittel 2,5 ZE je Satellit, 30 Läufe je Konfiguration.
A30: Quelle der Zahlen | B30: protokoll.txt sowie die CSV-Dateien des Simulationslaufs. Quellcode und Ergebnisdateien liegen im öffentlichen Repository, die Herleitung aller Parameter in Anhang F.

Sheet Kernzahlen
A1: Befund | B1: Wert | C1: Einheit | D1: Herkunft
A2: Produktionsorganisation bei drei Prüfstationen
A3: Programmdauer 1 × 30 | B3: ='E1 Produktionsorganisation'!C17 -> 605.56552 | C3: ZE | D3: E1
A4: Programmdauer 15 × 2 | B4: ='E1 Produktionsorganisation'!C23 -> 430.81569 | C4: ZE | D4: E1
A5: Verkürzung | B5: =1-B4/B3 -> 0.28857294 | C5: Anteil | D5: berechnet
A6: Hochlaufdauer 1 × 30 | B6: ='E1 Produktionsorganisation'!F17 -> 152.83771 | C6: ZE | D6: E1
A7: Hochlaufdauer 15 × 2 | B7: ='E1 Produktionsorganisation'!F23 -> 85.516624 | C7: ZE | D7: E1
A8: Ausbringungsrate 15 × 2 | B8: ='E1 Produktionsorganisation'!E23 -> 0.4623137 | C8: Satelliten je ZE | D8: E1
A9: Prüfkapazität als Begrenzung
A10: Rechnerische Kapazität einer Prüfstation | B10: =1/2.5 -> 0.4 | C10: Satelliten je ZE | D10: Prüfdauer 2,5 ZE
A11: Ausbringungsrate 5 × 6 bei einer Prüfstation | B11: ='E1 Produktionsorganisation'!E6 -> 0.39853304 | C11: Satelliten je ZE | D11: E1
A12: Ausbringungsrate 15 × 2 bei einer Prüfstation | B12: ='E1 Produktionsorganisation'!E9 -> 0.40561849 | C12: Satelliten je ZE | D12: E1
A13: Auslastung der Prüfung 15 × 2 bei einer Prüfstation | B13: ='E1 Produktionsorganisation'!G9 -> 0.91520561 | C13: Anteil | D13: E1
A14: Programmdauer 15 × 2 bei einer Prüfstation | B14: ='E1 Produktionsorganisation'!C9 -> 491.87127 | C14: ZE | D14: E1
A15: Programmdauer 15 × 2 bei zwei Prüfstationen | B15: ='E1 Produktionsorganisation'!C16 -> 428.24398 | C15: ZE | D15: E1
A16: Programmdauer 15 × 2 bei drei Prüfstationen | B16: ='E1 Produktionsorganisation'!C23 -> 430.81569 | C16: ZE | D16: E1
A17: Auslastung der Prüfung 15 × 2 bei drei Prüfstationen | B17: ='E1 Produktionsorganisation'!G23 -> 0.34796467 | C17: Anteil | D17: E1
A18: Standardisierung und Automatisierung, 5 × 6 bei drei Prüfstationen
A19: beide niedrig (r = 0,30 und k = 1,0) | B19: ='E2 Standardis. Automatisierung'!G30 -> 622.77383 | C19: ZE | D19: E2
A20: beide hoch (r = 0,10 und k = 0,6) | B20: ='E2 Standardis. Automatisierung'!G38 -> 368.53637 | C20: ZE | D20: E2
A21: Verkürzung | B21: =1-B20/B19 -> 0.40823401 | C21: Anteil | D21: berechnet
A22: Automatisierung hoch (k = 0,6), Standardisierung mittel (r = 0,20) | B22: ='E2 Standardis. Automatisierung'!G35 -> 393.97159 | C22: ZE | D22: E2
A23: Standardisierung hoch (r = 0,10), Automatisierung mittel (k = 0,8) | B23: ='E2 Standardis. Automatisierung'!G37 -> 466.89867 | C23: ZE | D23: E2
A24: Standardisierung und Variantenwechsel, 5 × 6 bei drei Prüfstationen
A25: 10 % Wechsel, niedrige Standardisierung (r = 0,30) | B25: ='E4 Portfolio Standardisierung'!F30 -> 475.409 | C25: ZE | D25: E4
A26: 10 % Wechsel, hohe Standardisierung (r = 0,10) | B26: ='E4 Portfolio Standardisierung'!F32 -> 452.54331 | C26: ZE | D26: E4
A27: Wirkung bei 10 % Wechsel | B27: =B25-B26 -> 22.865692 | C27: ZE | D27: berechnet
A28: 50 % Wechsel, niedrige Standardisierung (r = 0,30) | B28: ='E4 Portfolio Standardisierung'!F36 -> 560.57718 | C28: ZE | D28: E4
A29: 50 % Wechsel, hohe Standardisierung (r = 0,10) | B29: ='E4 Portfolio Standardisierung'!F38 -> 475.7555 | C29: ZE | D29: E4
A30: Wirkung bei 50 % Wechsel | B30: =B28-B29 -> 84.821673 | C30: ZE | D30: berechnet
A31: Fertigungstiefe, 5 × 6 bei drei Prüfstationen
A32: Programmdauer bei Fertigungstiefe 0,5 | B32: ='E3 Fertigungstiefe'!D27 -> 401.51218 | C32: ZE | D32: E3
A33: Programmdauer bei Fertigungstiefe 0,65 | B33: ='E3 Fertigungstiefe'!D34 -> 492.70238 | C33: ZE | D33: E3
A34: Programmdauer bei Fertigungstiefe 0,8 | B34: ='E3 Fertigungstiefe'!D41 -> 586.92009 | C34: ZE | D34: E3
A35: Fehlteile je Satellit bei Fertigungstiefe 0,5 | B35: ='E3 Fertigungstiefe'!F27 -> 0.8887037 | C35: Stück | D35: E3
A36: Fehlteile je Satellit bei Fertigungstiefe 0,8 | B36: ='E3 Fertigungstiefe'!F41 -> 0.3612963 | C36: Stück | D36: E3
A37: Kipppunkt der Lieferverzögerung, 5 × 6 bei drei Prüfstationen
A38: Wartezeit 3 ZE, Fertigungstiefe 0,5 | B38: ='E3b Lieferverzögerung'!C3 -> 401.51218 | C38: ZE | D38: E3b Lieferverzögerung
A39: Wartezeit 3 ZE, Fertigungstiefe 0,65 | B39: ='E3b Lieferverzögerung'!C4 -> 492.70238 | C39: ZE | D39: E3b Lieferverzögerung
A40: Wartezeit 3 ZE, Fertigungstiefe 0,8 | B40: ='E3b Lieferverzögerung'!C5 -> 586.92009 | C40: ZE | D40: E3b Lieferverzögerung
...

Sheet E1 Produktionsorganisation
A1: E1 Produktionsorganisation und Prüfkapazität. Variiert werden die Aufteilung der 30 Stationsplätze auf Linien und Stationen sowie die Anzahl der Prüfstationen. Konstant bleiben v = 0,30, r = 0,20, k = 0,80 und f = 0,65.
A2: Prüfstationen | B2: Konfiguration | C2: Programmdauer in ZE | D2: Konfidenzintervall ± | E2: Ausbringungsrate je ZE | F2: Hochlaufdauer in ZE | G2: Auslastung der Prüfung
A3: 1 | B3: 1 × 30 | C3: 607.47979 | D3: 8.7812659 | E3: 0.34572949 | F3: 191.38324 | G3: 0.74353619
A4: 1 | B4: 2 × 15 | C4: 548.70364 | D4: 5.0476222 | E4: 0.38701504 | F4: 170.73306 | G4: 0.82636481
A5: 1 | B5: 3 × 10 | C5: 527.7333 | D5: 3.9762743 | E5: 0.38944078 | F5: 163.79198 | G5: 0.8516319
A6: 1 | B6: 5 × 6 | C6: 510.03954 | D6: 3.0402275 | E6: 0.39853304 | F6: 139.24017 | G6: 0.88384358
A7: 1 | B7: 6 × 5 | C7: 506.28693 | D7: 2.9176482 | E7: 0.40720664 | F7: 145.72609 | G7: 0.88858249
A8: 1 | B8: 10 × 3 | C8: 495.90462 | D8: 3.5023703 | E8: 0.40721605 | F8: 132.2213 | G8: 0.90363742
A9: 1 | B9: 15 × 2 | C9: 491.87127 | D9: 4.0133883 | E9: 0.40561849 | F9: 130.02712 | G9: 0.91520561
A10: 2 | B10: 1 × 30 | C10: 602.73699 | D10: 7.1850746 | E10: 0.35728586 | F10: 159.42215 | G10: 0.37213663
A11: 2 | B11: 2 × 15 | C11: 549.58109 | D11: 5.7309225 | E11: 0.36949016 | F11: 134.99623 | G11: 0.40867926
A12: 2 | B12: 3 × 10 | C12: 522.15423 | D12: 3.1663313 | E12: 0.39527025 | F12: 136.04491 | G12: 0.43068946
A13: 2 | B13: 5 × 6 | C13: 488.92182 | D13: 3.2027941 | E13: 0.430346 | F13: 128.54598 | G13: 0.45882633
A14: 2 | B14: 6 × 5 | C14: 484.20925 | D14: 3.3536927 | E14: 0.42646605 | F14: 122.47239 | G14: 0.4617461
... A23: 3 | B23: 15 × 2 | C23: 430.81569 | D23: 3.810032 | E23: 0.4623137 | F23: 85.516624 | G23: 0.34796467

Sheet E2 Standardis. Automatisierung
A1: E2 Standardisierung und Automatisierung. Variiert werden der Anpassungsanteil r und der Zeitfaktor k_auto, jeweils in drei Ausprägungen, für eine lange Linie (1 × 30) und eine aufgeteilte Fertigung (5 × 6), jeweils bei knapper (K = 1) und ausreichender Prüfkapazität (K = 3). Konstant bleiben v = 0,30 und f = 0,65.
A2: Konfiguration | B2: Prüfstationen | C2: Standardisierung | D2: Anpassungsanteil r | E2: Automatisierung | F2: Zeitfaktor k_auto | G2: Programmdauer in ZE | H2: Konfidenzintervall ± | I2: Ausbringungsrate je ZE
A3: 1 × 30 | B3: 1 | C3: niedrig | D3: 0.3 | E3: niedrig | F3: 1 | G3: 732.80808 | H3: 7.3469591 | I3: 0.29017705
A4: 1 × 30 | B4: 1 | C4: niedrig | D4: 0.3 | E4: mittel | F4: 0.8 | G4: 643.80525 | H4: 5.6770296 | I4: 0.31732512
A5: 1 × 30 | B5: 1 | C5: niedrig | D5: 0.3 | E5: hoch | F5: 0.6 | G5: 555.70512 | H5: 5.6776048 | I5: 0.37071121
A6: 1 × 30 | B6: 1 | C6: mittel | D6: 0.2 | E6: niedrig | F6: 1 | G6: 701.22094 | H6: 7.2448443 | I6: 0.29859849
A7: 1 × 30 | B7: 1 | C7: mittel | D7: 0.2 | E7: mittel | F7: 0.8 | G7: 607.47979 | H7: 8.7812659 | I7: 0.34572949
A8: 1 × 30 | B8: 1 | C8: mittel | D8: 0.2 | E8: hoch | F8: 0.6 | G8: 522.27035 | H8: 5.7600805 | I8: 0.39371837
A9: 1 × 30 | B9: 1 | C9: hoch | D9: 0.1 | E9: niedrig | F9: 1 | G9: 672.77809 | H9: 9.0789483 | I9: 0.31771101
A10: 1 × 30 | B10: 1 | C10: hoch | D10: 0.1 | E10: mittel | F10: 0.8 | G10: 579.12658 | H10: 8.0137283 | I10: 0.36713118
A11: 1 × 30 | B11: 1 | C11: hoch | D11: 0.1 | E11: hoch | F11: 0.6 | G11: 511.49393 | H11: 4.6110024 | I11: 0.39998985
A12: 1 × 30 | B12: 3 | C12: niedrig | D12: 0.3 | E12: niedrig | F12: 1 | G12: 731.7296 | H12: 6.3089144 | I12: 0.28413047
A13: 1 × 30 | B13: 3 | C13: niedrig | D13: 0.3 | E13: mittel | F13: 0.8 | G13: 640.58953 | H13: 7.1410379 | I13: 0.33123826
A14: 1 × 30 | B14: 3 | C14: niedrig | D14: 0.3 | E14: hoch | F14: 0.6 | G14: 555.77635 | H14: 8.0639523 | I14: 0.38140016
... A38: 5 × 6 | B38: 3 | C38: hoch | D38: 0.1 | E38: hoch | F38: 0.6 | G38: 368.53637 | H38: 2.7640304 | I38: 0.56594955

Sheet E3 Fertigungstiefe
A1: E3 Fertigungstiefe. Variiert wird der Anteil des intern gefertigten Arbeitsinhalts f über alle sieben Linienaufteilungen, bei knapper (K = 1) und ausreichender Prüfkapazität (K = 3). Konstant bleiben v = 0,30, r = 0,20 und k = 0,80.
A2: Prüfstationen | B2: Fertigungstiefe | C2: Konfiguration | D2: Programmdauer in ZE | E2: Konfidenzintervall ± | F2: Fehlteile je Satellit | G2: Ausbringungsrate je ZE
A3: 1 | B3: 0.5 | C3: 1 × 30 | D3: 546.8577 | E3: 7.763068 | F3: 0.87148148 | G3: 0.36773383
A4: 1 | B4: 0.5 | C4: 2 × 15 | D4: 503.01378 | E4: 4.0033921 | F4: 0.90148148 | G4: 0.39129871
A5: 1 | B5: 0.5 | C5: 3 × 10 | D5: 496.14009 | E5: 3.2681564 | F5: 0.89037037 | G5: 0.40098083
A6: 1 | B6: 0.5 | C6: 5 × 6 | D6: 488.07932 | E6: 3.3986568 | F6: 0.89074074 | G6: 0.40468842
A7: 1 | B7: 0.5 | C7: 6 × 5 | D7: 490.84522 | E7: 3.2093546 | F7: 0.89 | G7: 0.39842936
A8: 1 | B8: 0.5 | C8: 10 × 3 | D8: 486.64636 | E8: 3.2804778 | F8: 0.88648148 | G8: 0.3945405
A9: 1 | B9: 0.5 | C9: 15 × 2 | D9: 481.00466 | E9: 3.2606459 | F9: 0.9212963 | G9: 0.39312046
A10: 1 | B10: 0.65 | C10: 1 × 30 | D10: 607.47979 | E10: 8.7812659 | F10: 0.62296296 | G10: 0.34572949
A11: 1 | B11: 0.65 | C11: 2 × 15 | D11: 548.70364 | E11: 5.0476222 | F11: 0.62462963 | G11: 0.38701504
A12: 1 | B12: 0.65 | C12: 3 × 10 | D12: 527.7333 | E12: 3.9762743 | F12: 0.64074074 | G12: 0.38944078
A13: 1 | B13: 0.65 | C13: 5 × 6 | D13: 510.03954 | E13: 3.0402275 | F13: 0.62185185 | G13: 0.39853304
A14: 1 | B14: 0.65 | C14: 6 × 5 | D14: 506.28693 | E14: 2.9176482 | F14: 0.64018519 | G14: 0.40720664
... A44: 3 | B44: 0.8 | C44: 15 × 2 | D44: 517.53646 | E44: 5.298322 | F44: 0.35537037 | G44: 0.38376964

Sheet E3b Lieferverzögerung
A1: E3 Kipppunkt der Lieferverzögerung. Variiert wird die mittlere Wartezeit je Fehlteil für die drei Fertigungstiefen, in der Konfiguration 5 × 6 bei drei Prüfstationen. Gesucht ist die Wartezeit, ab der die höhere Fertigungstiefe vorteilhaft wird.
A2: Mittlere Wartezeit je Fehlteil in ZE | B2: Fertigungstiefe | C2: Programmdauer in ZE | D2: Konfidenzintervall ±
A3: 3 | B3: 0.5 | C3: 401.51218 | D3: 4.1807285
A4: 3 | B4: 0.65 | C4: 492.70238 | D4: 3.4732707
A5: 3 | B5: 0.8 | C5: 586.92009 | D5: 4.5975545
A6: 6 | B6: 0.5 | C6: 466.91093 | D6: 7.0544334
A7: 6 | B7: 0.65 | C7: 541.30476 | D7: 4.4192376
A8: 6 | B8: 0.8 | C8: 614.16876 | D8: 6.7046385
A9: 10 | B9: 0.5 | C9: 574.40838 | D9: 11.025981
A10: 10 | B10: 0.65 | C10: 607.89847 | D10: 8.3464147
A11: 10 | B11: 0.8 | C11: 649.57763 | D11: 8.0485202
A12: 15 | B12: 0.5 | C12: 700.42832 | D12: 14.010726
A13: 15 | B13: 0.65 | C13: 721.912 | D13: 15.499769
A14: 15 | B14: 0.8 | C14: 717.61608 | D14: 10.996319
... A20: 30 | B20: 0.8 | C20: 911.02751 | D20: 27.290052

Sheet E4 Portfolio Standardisierung
A1: E4 Produktportfolio und Standardisierung. Variiert werden die Wechselwahrscheinlichkeit v und der Anpassungsanteil r, für eine lange Linie (1 × 30) und eine aufgeteilte Fertigung (5 × 6), jeweils bei knapper (K = 1) und ausreichender Prüfkapazität (K = 3). Konstant bleiben k = 0,80 und f = 0,65.
A2: Konfiguration | B2: Prüfstationen | C2: Wechselwahrscheinlichkeit | D2: Standardisierung | E2: Anpassungsanteil r | F2: Programmdauer in ZE | G2: Konfidenzintervall ±
A3: 1 × 30 | B3: 1 | C3: 0.1 | D3: niedrig | E3: 0.3 | F3: 598.6208 | G3: 9.4028998
A4: 1 × 30 | B4: 1 | C4: 0.1 | D4: mittel | E4: 0.2 | F4: 579.47504 | G4: 7.5960624
A5: 1 × 30 | B5: 1 | C5: 0.1 | D5: hoch | E5: 0.1 | F5: 562.56534 | G5: 6.8344435
A6: 1 × 30 | B6: 1 | C6: 0.3 | D6: niedrig | E6: 0.3 | F6: 643.80525 | G6: 5.6770296
A7: 1 × 30 | B7: 1 | C7: 0.3 | D7: mittel | E7: 0.2 | F7: 607.47979 | G7: 8.7812659
A8: 1 × 30 | B8: 1 | C8: 0.3 | D8: hoch | E8: 0.1 | F8: 579.12658 | G8: 8.0137283
A9: 1 × 30 | B9: 1 | C9: 0.5 | D9: niedrig | E9: 0.3 | F9: 670.42474 | G9: 6.4521995
A10: 1 × 30 | B10: 1 | C10: 0.5 | D10: mittel | E10: 0.2 | F10: 627.5287 | G10: 9.0522131
A11: 1 × 30 | B11: 1 | C11: 0.5 | D11: hoch | E11: 0.1 | F11: 582.89151 | G11: 5.5628041
A12: 1 × 30 | B12: 3 | C12: 0.1 | D12: niedrig | E12: 0.3 | F12: 598.43052 | G12: 7.0772411
A13: 1 × 30 | B13: 3 | C13: 0.1 | D13: mittel | E13: 0.2 | F13: 579.73059 | G13: 9.8486515
A14: 1 × 30 | B14: 3 | C14: 0.1 | D14: hoch | E14: 0.1 | F14: 562.93335 | G14: 7.0019404
... A38: 5 × 6 | B38: 3 | C38: 0.5 | D38: hoch | E38: 0.1 | F38: 475.7555 | G38: 3.652633

Sheet Sensitivität
A1: Sensitivitätsanalyse. Jede Zeile ist ein kompletter Satz Simulationsläufe mit einer veränderten Modellannahme. Die vier Programmdauern sind die Vergleichswerte, aus denen sich die Befunde B1 bis B4 ergeben. Die letzten vier Spalten sagen, ob der jeweilige Befund unter dieser Annahme weiterhin gilt. Erklärung von B1 bis B4 unterhalb der Tabelle.
A2: Einstellung | B2: Programmdauer 1 × 30 bei K = 1 | C2: Programmdauer 1 × 30 bei K = 3 | D2: Programmdauer 15 × 2 bei K = 1 | E2: Programmdauer 15 × 2 bei K = 3 | F2: B1 | G2: B2 | H2: B3 | I2: B4
A3: Referenzfall | B3: 607.47979 | C3: 605.56552 | D3: 491.87127 | E3: 430.81569 | F3: hält | G3: hält | H3: hält | I3: hält
A4: Mindestzeit 0,65 | B4: 574.38777 | C4: 571.61221 | D4: 488.80501 | E4: 411.75061 | F4: hält | G4: hält | H4: hält | I4: hält
A5: Mindestzeit 0,85 | B5: 637.81404 | C5: 625.91326 | D5: 490.58415 | E5: 443.4741 | F5: hält | G5: hält | H5: hält | I5: hält
A6: Streuung CV 0,15 | B6: 575.81391 | C6: 565.46815 | D6: 495.62553 | E6: 404.44741 | F6: hält | G6: hält | H6: hält | I6: hält
A7: Streuung CV 0,45 | B7: 658.89952 | C7: 660.45678 | D7: 494.8612 | E7: 457.17064 | F7: hält | G7: hält | H7: hält | I7: hält
A8: Pruefdauer 1,5 ZE | B8: 602.9723 | C8: 604.50166 | D8: 427.28018 | E8: 427.89469 | F8: hält | G8: hält | H8: hält | I8: hält
A9: Pruefdauer 3,5 ZE | B9: 696.57748 | C9: 606.45183 | D9: 670.76079 | E9: 427.85406 | F9: hält | G9: hält | H9: hält nicht | I9: hält
A11: B1 Die Aufteilung auf mehrere Linien verkürzt die Programmdauer.
A12: B2 Der Gewinn der Aufteilung fällt größer aus, wenn die Prüfkapazität ausreicht.
A13: B3 Bei einer einzelnen langen Linie bringt zusätzliche Prüfkapazität keinen Vorteil.
A14: B4 Standardisierung wirkt vor allem bei hohem Variantenanteil.

Sheet Verifikation
A1: Verifikation durch Grenzwerttests. Einzelne Einflüsse werden entfernt oder verstärkt und geprüft, ob die Programmdauer in die erwartete Richtung reagiert. Konfiguration 5 × 6 mit drei Prüfstationen, je 30 Läufe.
A2: Grenzwerttest | B2: Programmdauer in ZE | C2: erwartete Richtung
A3: Basislauf | B3: 492.7 | C3: Referenz
A4: ohne Erfahrungseffekt | B4: 541.9 | C4: länger
A5: ohne Mindestzeit | B5: 353.9 | C5: kürzer
A6: ohne Variantenwechsel | B6: 447.4 | C6: kürzer
A7: ohne Streuung | B7: 436.6 | C7: kürzer
A8: volle Fertigungstiefe | B8: 713.8 | C8: länger
A9: ohne Automatisierungsvorteil | B9: 588.4 | C9: länger
A10: eine Prüfstation | B10: 510 | C10: länger
A12: Konfiguration 5 × 6, drei Prüfstationen, je 30 Läufe. Quelle: protokoll.txt, Block V.

Sheet Parameter
A1: Ausprägungen der Modellgrößen. Der Ausgangsvergleich ist die Konfiguration, von der aus jeweils einzelne Größen verändert werden. Die vollständige Herleitung der Werte steht in Anhang F der Arbeit.
A2: Modellgröße | B2: Ausprägung | C2: Wert im Modell | D2: Bedeutung
A3: Produktportfolio v | B3: niedrig | C3: 0.1 | D3: Wahrscheinlichkeit eines Variantenwechsels je Satellit
A4: Produktportfolio v | B4: Ausgangsvergleich | C4: 0.3
A5: Produktportfolio v | B5: hoch | C5: 0.5
A6: Standardisierung r | B6: niedrig | C6: 0.3 | D6: Anpassungsaufwand je Station als Anteil der nominalen Stationszeit
A7: Standardisierung r | B7: Ausgangsvergleich | C7: 0.2 | D7: Ein höherer Standardisierungsgrad bedeutet ein kleineres r
A8: Standardisierung r | B8: hoch | C8: 0.1
A9: Automatisierung k_auto | B9: niedrig | C9: 1 | D9: Faktor auf die reguläre Bearbeitungszeit, 1,0 heißt kein Vorteil
A10: Automatisierung k_auto | B10: Ausgangsvergleich | C10: 0.8
A11: Automatisierung k_auto | B11: hoch | C11: 0.6
A12: Fertigungstiefe f | B12: niedrig | C12: 0.5 | D12: Anteil des intern gefertigten Arbeitsinhalts
A13: Fertigungstiefe f | B13: Ausgangsvergleich | C13: 0.65
A14: Fertigungstiefe f | B14: hoch | C14: 0.8
A15: Prüfstationen K | B15: knapp | C15: 1 | D15: Gemeinsame Prüfung aller Linien, Prüfdauer im Mittel 2,5 ZE
A16: Prüfstationen K | B16: ausreichend | C16: 2
A17: Prüfstationen K | B17: Ausgangsvergleich | C17: 3
A19: Alle Zeiten sind normierte Zeiteinheiten (ZE). Programmumfang 180 Satelliten, 30 Stationsplätze, 30 Läufe je Konfiguration.
