Workbook

Sheet Lesehilfe
A1: Ergebnisse der Modellbetrachtung | B1: Begleitmappe zu Abschnitt 6.3 der Masterarbeit
A3: Was diese Mappe enthält | B3: Alle Ergebnisse des ereignisdiskreten Ablaufmodells zur Skalierbarkeit der Satellitenfertigung. Die Zahlen stammen aus einem Lauf des Simulationsskripts und sind durch feste Startwerte des Zufallsgenerators wiederholbar.
A4: So liest sich die Mappe | B4: Jedes Blatt verändert genau eine Größe und hält die übrigen fest. Die gelb hinterlegte Zeile ist jeweils der Ausgangsvergleich. Ein Unterschied ist nur dann belastbar, wenn er größer ist als die beiden Konfidenzintervalle zusammen.
A6: Blätter
A7: Kernzahlen | B7: Die Werte, auf die sich die Auswertung stützt, nach Befund gruppiert.
A8: Produktionsorganisation | B8: Aufteilung der 30 Stationsplätze und Zahl der Prüfstationen.
A9: Standardisierung | B9: Anpassungsaufwand bei Variantenwechsel und Zeitfaktor der Automatisierung.
A10: Fertigungstiefe | B10: Anteil des intern gefertigten Arbeitsinhalts.
A11: Fertigungstiefe Zulieferzeit | B11: Dieselbe Frage bei steigender Wartezeit auf Zukaufteile.
A12: Produktportfolio | B12: Häufigkeit der Variantenwechsel und Wirkung der Standardisierung.
A13: Sensitivitätsanalyse | B13: Halten die Befunde auch bei veränderten Annahmen?
A14: Verifikation | B14: Grenzwerttests zur Prüfung der Modelllogik.
A15: Parameter | B15: Alle Ausprägungen der Modellgrößen im Überblick.
A17: Ergebnisgrößen
A18: Programmdauer | B18: Zeitpunkt, zu dem der letzte der 180 Satelliten die Prüfung abgeschlossen hat. Kleiner ist besser.
A19: Ausbringungsrate | B19: Fertiggestellte Satelliten je Zeiteinheit am Programmende. Größer ist besser.
A20: Hochlaufdauer | B20: Zeitpunkt, ab dem die Ausbringungsrate erstmals 95 % ihres Endwerts erreicht.
A21: Auslastung der Prüfung | B21: Anteil der Programmdauer, in dem die Prüfstationen belegt sind.
A22: Fehlteile je Satellit | B22: Mittlere Zahl fehlender Zukaufteile je Satellit. Steigt mit sinkender Fertigungstiefe.
A23: Konfidenzintervall ± | B23: Halbe Breite des 95-%-Konfidenzintervalls über 30 Läufe.
A25: Modellgrößen
A26: Konfiguration 1 × 30 bis 15 × 2 | B26: Linien mal Stationen je Linie. In allen Fällen zusammen 30 Stationsplätze.
A27: Prüfstationen K | B27: Zahl der Prüfstationen, die sich alle Linien teilen.
A28: Wechselwahrscheinlichkeit v | B28: Wie häufig sich ein Satellit vom zuvor auf derselben Linie gefertigten unterscheidet.
A29: Anpassungsanteil r | B29: Zusätzliche Zeit je Station bei einem Variantenwechsel, als Anteil der Stationszeit. Mehr Standardisierung bedeutet ein kleineres r.
A30: Zeitfaktor k | B30: Faktor auf die reguläre Bearbeitungszeit. Mehr Automatisierung bedeutet ein kleineres k.
A31: Fertigungstiefe f | B31: Anteil des intern gefertigten Arbeitsinhalts.
A32: ZE | B32: Normierte Zeiteinheit. Die Werte sind untereinander vergleichbar, aber keine realen Minuten oder Stunden.
A34: Rahmen des Modells | B34: 180 Satelliten je Programm, 30 Stationsplätze, keine Zwischenpuffer, gemeinsame Prüfung mit im Mittel 2,5 ZE je Satellit, 30 Läufe je Konfiguration.
A35: Herkunft der Zahlen | B35: Simulationsprotokoll und CSV-Dateien des Laufs. Die Herleitung aller Annahmen steht in Anhang F der Arbeit.

Sheet Kernzahlen
A1: Zentrale Werte der Modellbetrachtung
A2: Die Werte, auf die sich die Auswertung stützt. Jede Zahl ist mit der Zelle im jeweiligen Datenblatt verknüpft und ändert sich mit, wenn dort etwas angepasst wird.
A4: Befund | B4: Wert | C4: Einheit | D4: Datenblatt
A5: Aufteilung der Stationsplätze, drei Prüfstationen
A6: Programmdauer der langen Linie 1 × 30 | B6: =Produktionsorganisation!B22 -> 605.56552 | C6: ZE | D6: Produktionsorganisation
A7: Programmdauer der feinsten Aufteilung 15 × 2 | B7: =Produktionsorganisation!B28 -> 430.81569 | C7: ZE | D7: Produktionsorganisation
A8: Verkürzung der Programmdauer | B8: =1-B7/B6 -> 0.28857294 | C8: Anteil | D8: berechnet
A9: Hochlaufdauer der langen Linie 1 × 30 | B9: =Produktionsorganisation!F22 -> 152.83771 | C9: ZE | D9: Produktionsorganisation
A10: Hochlaufdauer der feinsten Aufteilung 15 × 2 | B10: =Produktionsorganisation!F28 -> 85.516624 | C10: ZE | D10: Produktionsorganisation
A11: Verkürzung der Hochlaufdauer | B11: =1-B10/B9 -> 0.44047431 | C11: Anteil | D11: berechnet
A12: Prüfkapazität als Begrenzung
A13: Rechnerische Kapazität einer Prüfstation | B13: =1/2.5 -> 0.4 | C13: Satelliten je ZE | D13: Prüfdauer 2,5 ZE
A14: Ausbringungsrate 15 × 2 bei einer Prüfstation | B14: =Produktionsorganisation!D12 -> 0.40561849 | C14: Satelliten je ZE | D14: Produktionsorganisation
A15: Ausbringungsrate 15 × 2 bei drei Prüfstationen | B15: =Produktionsorganisation!D28 -> 0.4623137 | C15: Satelliten je ZE | D15: Produktionsorganisation
A16: Zuwachs der Ausbringungsrate | B16: =B15/B14-1 -> 0.13977471 | C16: Anteil | D16: berechnet
A17: Auslastung der Prüfung 15 × 2 bei einer Prüfstation | B17: =Produktionsorganisation!G12 -> 0.91520561 | C17: Anteil | D17: Produktionsorganisation
A18: Auslastung der Prüfung 15 × 2 bei drei Prüfstationen | B18: =Produktionsorganisation!G28 -> 0.34796467 | C18: Anteil | D18: Produktionsorganisation
A19: Standardisierung und Automatisierung, 5 × 6 bei drei Prüfstationen
A20: beide niedrig, r = 0,30 und k = 1,00 | B20: =Standardisierung!G32 -> 622.77383 | C20: ZE | D20: Standardisierung
A21: beide hoch, r = 0,10 und k = 0,60 | B21: =Standardisierung!G40 -> 368.53637 | C21: ZE | D21: Standardisierung
A22: Verkürzung zwischen beiden Enden | B22: =1-B21/B20 -> 0.40823401 | C22: Anteil | D22: berechnet
A23: Wirkung der Standardisierung je nach Produktportfolio, 5 × 6 bei drei Prüfstationen
A24: 10 % Wechselwahrscheinlichkeit, niedrige Standardisierung | B24: =Produktportfolio!F36 -> 475.409 | C24: ZE | D24: Produktportfolio
A25: 10 % Wechselwahrscheinlichkeit, hohe Standardisierung | B25: =Produktportfolio!F38 -> 452.54331 | C25: ZE | D25: Produktportfolio
A26: Wirkung bei 10 % Wechselwahrscheinlichkeit | B26: =1-B25/B24 -> 0.048096885 | C26: Anteil | D26: berechnet
A27: 50 % Wechselwahrscheinlichkeit, niedrige Standardisierung | B27: =Produktportfolio!F42 -> 560.57718 | C27: ZE | D27: Produktportfolio
A28: 50 % Wechselwahrscheinlichkeit, hohe Standardisierung | B28: =Produktportfolio!F44 -> 475.7555 | C28: ZE | D28: Produktportfolio
A29: Wirkung bei 50 % Wechselwahrscheinlichkeit | B29: =1-B28/B27 -> 0.15131132 | C29: Anteil | D29: berechnet
A30: Fertigungstiefe, 5 × 6 bei drei Prüfstationen
A31: Programmdauer bei Fertigungstiefe 0,50 | B31: =Fertigungstiefe!D31 -> 401.51218 | C31: ZE | D31: Fertigungstiefe
A32: Programmdauer bei Fertigungstiefe 0,65 | B32: =Fertigungstiefe!D38 -> 492.70238 | C32: ZE | D32: Fertigungstiefe
A33: Programmdauer bei Fertigungstiefe 0,80 | B33: =Fertigungstiefe!D45 -> 586.92009 | C33: ZE | D33: Fertigungstiefe
A34: Abstand zwischen 0,50 und 0,80 | B34: =1-B31/B33 -> 0.31589975 | C34: Anteil | D34: berechnet
A35: Fehlteile je Satellit bei Fertigungstiefe 0,50 | B35: =Fertigungstiefe!F31 -> 0.8887037 | C35: Stück | D35: Fertigungstiefe
A36: Fehlteile je Satellit bei Fertigungstiefe 0,80 | B36: =Fertigungstiefe!F45 -> 0.3612963 | C36: Stück | D36: Fertigungstiefe
A37: Kipppunkt bei steigender Zulieferzeit, 5 × 6 bei drei Prüfstationen
A38: Zulieferzeit 3 ZE, Fertigungstiefe 0,50 | B38: ='Fertigungstiefe Zulieferzeit'!C6 -> 401.51218 | C38: ZE | D38: Fertigungstiefe Zulieferzeit
A39: Zulieferzeit 3 ZE, Fertigungstiefe 0,65 | B39: ='Fertigungstiefe Zulieferzeit'!C7 -> 492.70238 | C39: ZE | D39: Fertigungstiefe Zulieferzeit
A40: Zulieferzeit 3 ZE, Fertigungstiefe 0,80 | B40: ='Fertigungstiefe Zulieferzeit'!C8 -> 586.92009 | C40: ZE | D40: Fertigungstiefe Zulieferzeit
A41: Zulieferzeit 15 ZE, Fertigungstiefe 0,50 | B41: ='Fertigungstiefe Zulieferzeit'!C18 -> 700.42832 | C41: ZE | D41: Fertigungstiefe Zulieferzeit
...

Sheet Produktionsorganisation
A1: Produktionsorganisation und Prüfkapazität
A2: Dieselben 30 Stationsplätze werden unterschiedlich auf Linien aufgeteilt, von einer langen Linie (1 × 30) bis zu fünfzehn kurzen (15 × 2). Zusätzlich wird die Zahl der gemeinsam genutzten Prüfstationen verändert. Alles andere bleibt gleich. Vergleiche innerhalb eines Blocks von oben nach unten, die letzte Spalte zeigt die Veränderung gegenüber der langen Linie.
A4: Konfiguration | B4: Programmdauer in ZE | C4: Konfidenzintervall ± | D4: Ausbringungsrate je ZE | E4: Konfidenzintervall ± | F4: Hochlaufdauer in ZE | G4: Auslastung der Prüfung | H4: Veränderung der Programmdauer gegenüber 1 × 30
A5: Eine Prüfstation, knappe Prüfkapazität
A6: 1 × 30 | B6: 607.47979 | C6: 8.7812659 | D6: 0.34572949 | E6: 0.016205269 | F6: 191.38324 | G6: 0.74353619 | H6: =1-B6/B6 -> 0
A7: 2 × 15 | B7: 548.70364 | C7: 5.0476222 | D7: 0.38701504 | E7: 0.0086912567 | F7: 170.73306 | G7: 0.82636481 | H7: =1-B7/B6 -> 0.096754081
A8: 3 × 10 | B8: 527.7333 | C8: 3.9762743 | D8: 0.38944078 | E8: 0.0076206832 | F8: 163.79198 | G8: 0.8516319 | H8: =1-B8/B6 -> 0.13127431
A9: 5 × 6 | B9: 510.03954 | C9: 3.0402275 | D9: 0.39853304 | E9: 0.007563955 | F9: 139.24017 | G9: 0.88384358 | H9: =1-B9/B6 -> 0.1604008
A10: 6 × 5 | B10: 506.28693 | C10: 2.9176482 | D10: 0.40720664 | E10: 0.0075442804 | F10: 145.72609 | G10: 0.88858249 | H10: =1-B10/B6 -> 0.16657814
A11: 10 × 3 | B11: 495.90462 | C11: 3.5023703 | D11: 0.40721605 | E11: 0.0093198019 | F11: 132.2213 | G11: 0.90363742 | H11: =1-B11/B6 -> 0.18366895
A12: 15 × 2 | B12: 491.87127 | C12: 4.0133883 | D12: 0.40561849 | E12: 0.0090575188 | F12: 130.02712 | G12: 0.91520561 | H12: =1-B12/B6 -> 0.19030843
A13: Zwei Prüfstationen
A14: 1 × 30 | B14: 602.73699 | C14: 7.1850746 | D14: 0.35728586 | E14: 0.013760707 | F14: 159.42215 | G14: 0.37213663 | H14: =1-B14/B14 -> 0
A15: 2 × 15 | B15: 549.58109 | C15: 5.7309225 | D15: 0.36949016 | E15: 0.010664375 | F15: 134.99623 | G15: 0.40867926 | H15: =1-B15/B14 -> 0.088190885
A16: 3 × 10 | B16: 522.15423 | C16: 3.1663313 | D16: 0.39527025 | E16: 0.010195277 | F16: 136.04491 | G16: 0.43068946 | H16: =1-B16/B14 -> 0.13369474
A17: 5 × 6 | B17: 488.92182 | C17: 3.2027941 | D17: 0.430346 | E17: 0.011851028 | F17: 128.54598 | G17: 0.45882633 | H17: =1-B17/B14 -> 0.18883057
A18: 6 × 5 | B18: 484.20925 | C18: 3.3536927 | D18: 0.42646605 | E18: 0.013563415 | F18: 122.47239 | G18: 0.4617461 | H18: =1-B18/B14 -> 0.19664919
A19: 10 × 3 | B19: 452.32993 | C19: 3.4556426 | D19: 0.4521437 | E19: 0.011657518 | F19: 108.0336 | G19: 0.49577668 | H19: =1-B19/B14 -> 0.24954012
A20: 15 × 2 | B20: 428.24398 | C20: 4.7048745 | D20: 0.46166977 | E20: 0.015828145 | F20: 89.01853 | G20: 0.52423836 | H20: =1-B20/B14 -> 0.28950109
A21: Drei Prüfstationen, ausreichende Prüfkapazität
A22: 1 × 30 | B22: 605.56552 | C22: 7.616869 | D22: 0.33697284 | E22: 0.013607594 | F22: 152.83771 | G22: 0.24726225 | H22: =1-B22/B22 -> 0
A23: 2 × 15 | B23: 550.25711 | C23: 4.9955333 | D23: 0.37691612 | E23: 0.013175563 | F23: 140.86752 | G23: 0.27156207 | H23: =1-B23/B22 -> 0.091333475
A24: 3 × 10 | B24: 522.20983 | C24: 5.0273646 | D24: 0.38985045 | E24: 0.012168834 | F24: 130.87515 | G24: 0.28850226 | H24: =1-B24/B22 -> 0.13764932
A25: 5 × 6 | B25: 492.70238 | C25: 3.4732707 | D25: 0.41918134 | E25: 0.0085340609 | F25: 128.11764 | G25: 0.30347598 | H25: =1-B25/B22 -> 0.18637642
A26: 6 × 5 | B26: 484.08938 | C26: 3.239307 | D26: 0.42570069 | E26: 0.01018598 | F26: 122.03694 | G26: 0.30995053 | H26: =1-B26/B22 -> 0.20059949
A27: 10 × 3 | B27: 450.56467 | C27: 3.8933451 | D27: 0.44716349 | E27: 0.012420047 | F27: 103.85657 | G27: 0.333829 | H27: =1-B27/B22 -> 0.25596048
A28: 15 × 2 | B28: 430.81569 | C28: 3.810032 | D28: 0.4623137 | E28: 0.013239351 | F28: 85.516624 | G28: 0.34796467 | H28: =1-B28/B22 -> 0.28857294
A30: Die gelb hinterlegte Zeile ist der Ausgangsvergleich, von dem aus die übrigen Versuchsreihen einzelne Größen verändern.

Sheet Standardisierung
A1: Standardisierung und Automatisierung
A2: Verändert werden der Anpassungsaufwand je Station bei einem Variantenwechsel (r) und der Zeitfaktor der Automatisierung (k). Ein kleineres r bedeutet mehr Standardisierung, ein kleineres k mehr Automatisierung. Gezeigt werden die lange Linie und die aufgeteilte Fertigung, jeweils bei knapper und bei ausreichender Prüfkapazität.
A4: Konfiguration | B4: Prüfstationen | C4: Standardisierung | D4: Anpassungsanteil r | E4: Automatisierung | F4: Zeitfaktor k | G4: Programmdauer in ZE | H4: Konfidenzintervall ± | I4: Ausbringungsrate je ZE
A5: 1 × 30 | B5: 1 | C5: niedrig | D5: 0.3 | E5: niedrig | F5: 1 | G5: 732.80808 | H5: 7.3469591 | I5: 0.29017705
A6: 1 × 30 | B6: 1 | C6: niedrig | D6: 0.3 | E6: mittel | F6: 0.8 | G6: 643.80525 | H6: 5.6770296 | I6: 0.31732512
A7: 1 × 30 | B7: 1 | C7: niedrig | D7: 0.3 | E7: hoch | F7: 0.6 | G7: 555.70512 | H7: 5.6776048 | I7: 0.37071121
A8: 1 × 30 | B8: 1 | C8: mittel | D8: 0.2 | E8: niedrig | F8: 1 | G8: 701.22094 | H8: 7.2448443 | I8: 0.29859849
A9: 1 × 30 | B9: 1 | C9: mittel | D9: 0.2 | E9: mittel | F9: 0.8 | G9: 607.47979 | H9: 8.7812659 | I9: 0.34572949
A10: 1 × 30 | B10: 1 | C10: mittel | D10: 0.2 | E10: hoch | F10: 0.6 | G10: 522.27035 | H10: 5.7600805 | I10: 0.39371837
A11: 1 × 30 | B11: 1 | C11: hoch | D11: 0.1 | E11: niedrig | F11: 1 | G11: 672.77809 | H11: 9.0789483 | I11: 0.31771101
A12: 1 × 30 | B12: 1 | C12: hoch | D12: 0.1 | E12: mittel | F12: 0.8 | G12: 579.12658 | H12: 8.0137283 | I12: 0.36713118
A13: 1 × 30 | B13: 1 | C13: hoch | D13: 0.1 | E13: hoch | F13: 0.6 | G13: 511.49393 | H13: 4.6110024 | I13: 0.39998985
A14: 1 × 30 | B14: 3 | C14: niedrig | D14: 0.3 | E14: niedrig | F14: 1 | G14: 731.7296 | H14: 6.3089144 | I14: 0.28413047
A15: 1 × 30 | B15: 3 | C15: niedrig | D15: 0.3 | E15: mittel | F15: 0.8 | G15: 640.58953 | H15: 7.1410379 | I15: 0.33123826
A16: 1 × 30 | B16: 3 | C16: niedrig | D16: 0.3 | E16: hoch | F16: 0.6 | G16: 555.77635 | H16: 8.0639523 | I16: 0.38140016
... A40: 5 × 6 | B40: 3 | C40: hoch | D40: 0.1 | E40: hoch | F40: 0.6 | G40: 368.53637 | H40: 2.7640304 | I40: 0.56594955
A42: Mittel entspricht jeweils dem Ausgangsvergleich, also r = 0,20 und k = 0,80.

Sheet Fertigungstiefe
A1: Fertigungstiefe
A2: Verändert wird der Anteil des intern gefertigten Arbeitsinhalts. Eine geringere Fertigungstiefe bedeutet weniger eigene Arbeit, aber mehr Zukaufteile und damit mehr Fehlteile, auf die gewartet werden muss.
A4: Prüfstationen | B4: Fertigungstiefe f | C4: Konfiguration | D4: Programmdauer in ZE | E4: Konfidenzintervall ± | F4: Fehlteile je Satellit | G4: Ausbringungsrate je ZE
A5: Eine Prüfstation
A6: 1 | B6: 0.5 | C6: 1 × 30 | D6: 546.8577 | E6: 7.763068 | F6: 0.87148148 | G6: 0.36773383
A7: 1 | B7: 0.5 | C7: 2 × 15 | D7: 503.01378 | E7: 4.0033921 | F7: 0.90148148 | G7: 0.39129871
A8: 1 | B8: 0.5 | C8: 3 × 10 | D8: 496.14009 | E8: 3.2681564 | F8: 0.89037037 | G8: 0.40098083
A9: 1 | B9: 0.5 | C9: 5 × 6 | D9: 488.07932 | E9: 3.3986568 | F9: 0.89074074 | G9: 0.40468842
A10: 1 | B10: 0.5 | C10: 6 × 5 | D10: 490.84522 | E10: 3.2093546 | F10: 0.89 | G10: 0.39842936
A11: 1 | B11: 0.5 | C11: 10 × 3 | D11: 486.64636 | E11: 3.2804778 | F11: 0.88648148 | G11: 0.3945405
A12: 1 | B12: 0.5 | C12: 15 × 2 | D12: 481.00466 | E12: 3.2606459 | F12: 0.9212963 | G12: 0.39312046
A13: 1 | B13: 0.65 | C13: 1 × 30 | D13: 607.47979 | E13: 8.7812659 | F13: 0.62296296 | G13: 0.34572949
A14: 1 | B14: 0.65 | C14: 2 × 15 | D14: 548.70364 | E14: 5.0476222 | F14: 0.62462963 | G14: 0.38701504
A15: 1 | B15: 0.65 | C15: 3 × 10 | D15: 527.7333 | E15: 3.9762743 | F15: 0.64074074 | G15: 0.38944078
A16: 1 | B16: 0.65 | C16: 5 × 6 | D16: 510.03954 | E16: 3.0402275 | F16: 0.62185185 | G16: 0.39853304
A17: 1 | B17: 0.65 | C17: 6 × 5 | D17: 506.28693 | E17: 2.9176482 | F17: 0.64018519 | G17: 0.40720664
... A26: 1 | B26: 0.8 | C26: 15 × 2 | D26: 523.37127 | E26: 5.2517936 | F26: 0.36666667 | G26: 0.39008639
A27: Drei Prüfstationen
A28: 3 | B28: 0.5 | C28: 1 × 30 | D28: 541.29312 | E28: 6.7361076 | F28: 0.89814815 | G28: 0.39422561
A29: 3 | B29: 0.5 | C29: 2 × 15 | D29: 467.43932 | E29: 4.9255048 | F29: 0.92407407 | G29: 0.43269949
A30: 3 | B30: 0.5 | C30: 3 × 10 | D30: 431.05249 | E30: 3.9530962 | F30: 0.89722222 | G30: 0.4826273
A31: 3 | B31: 0.5 | C31: 5 × 6 | D31: 401.51218 | E31: 4.1807285 | F31: 0.8887037 | G31: 0.50332051
A32: 3 | B32: 0.5 | C32: 6 × 5 | D32: 388.38263 | E32: 3.8152754 | F32: 0.90018519 | G32: 0.54326223
A33: 3 | B33: 0.5 | C33: 10 × 3 | D33: 362.83621 | E33: 2.8916428 | F33: 0.89222222 | G33: 0.56007102
A34: 3 | B34: 0.5 | C34: 15 × 2 | D34: 341.81132 | E34: 3.2911023 | F34: 0.89740741 | G34: 0.58274657
A35: 3 | B35: 0.65 | C35: 1 × 30 | D35: 605.56552 | E35: 7.616869 | F35: 0.63537037 | G35: 0.33697284
A36: 3 | B36: 0.65 | C36: 2 × 15 | D36: 550.25711 | E36: 4.9955333 | F36: 0.62888889 | G36: 0.37691612
A37: 3 | B37: 0.65 | C37: 3 × 10 | D37: 522.20983 | E37: 5.0273646 | F37: 0.63907407 | G37: 0.38985045
A38: 3 | B38: 0.65 | C38: 5 × 6 | D38: 492.70238 | E38: 3.4732707 | F38: 0.64185185 | G38: 0.41918134
A39: 3 | B39: 0.65 | C39: 6 × 5 | D39: 484.08938 | E39: 3.239307 | F39: 0.62666667 | G39: 0.42570069
... A48: 3 | B48: 0.8 | C48: 15 × 2 | D48: 517.53646 | E48: 5.298322 | F48: 0.35537037 | G48: 0.38376964

Sheet Fertigungstiefe Zulieferzeit
A1: Fertigungstiefe bei steigender Zulieferzeit
A2: Verändert wird die mittlere Wartezeit auf ein fehlendes Zukaufteil, für drei Fertigungstiefen in der Konfiguration 5 × 6 mit drei Prüfstationen. Die letzte Spalte markiert, welche Fertigungstiefe bei der jeweiligen Zulieferzeit am schnellsten ist. Dort, wo die Markierung wechselt, liegt der Kipppunkt.
A4: Mittlere Zulieferzeit je Fehlteil in ZE | B4: Fertigungstiefe f | C4: Programmdauer in ZE | D4: Konfidenzintervall ± | E4: kürzeste Programmdauer
A5: Zulieferzeit 3 ZE
A6: 3 | B6: 0.5 | C6: 401.51218 | D6: 4.1807285 | E6: ja
A7: 3 | B7: 0.65 | C7: 492.70238 | D7: 3.4732707
A8: 3 | B8: 0.8 | C8: 586.92009 | D8: 4.5975545
A9: Zulieferzeit 6 ZE
A10: 6 | B10: 0.5 | C10: 466.91093 | D10: 7.0544334 | E10: ja
A11: 6 | B11: 0.65 | C11: 541.30476 | D11: 4.4192376
A12: 6 | B12: 0.8 | C12: 614.16876 | D12: 6.7046385
A13: Zulieferzeit 10 ZE
A14: 10 | B14: 0.5 | C14: 574.40838 | D14: 11.025981 | E14: ja
A15: 10 | B15: 0.65 | C15: 607.89847 | D15: 8.3464147
A16: 10 | B16: 0.8 | C16: 649.57763 | D16: 8.0485202
A17: Zulieferzeit 15 ZE
A18: 15 | B18: 0.5 | C18: 700.42832 | D18: 14.010726 | E18: ja
A19: 15 | B19: 0.65 | C19: 721.912 | D19: 15.499769
A20: 15 | B20: 0.8 | C20: 717.61608 | D20: 10.996319
A21: Zulieferzeit 20 ZE
A22: 20 | B22: 0.5 | C22: 830.56539 | D22: 21.86529
A23: 20 | B23: 0.65 | C23: 822.18968 | D23: 16.585661
A24: 20 | B24: 0.8 | C24: 779.90225 | D24: 9.5778539 | E24: ja
A25: Zulieferzeit 30 ZE
A26: 30 | B26: 0.5 | C26: 1124.4492 | D26: 36.858004
A27: 30 | B27: 0.65 | C27: 1008.9907 | D27: 32.199769
A28: 30 | B28: 0.8 | C28: 911.02751 | D28: 27.290052 | E28: ja

Sheet Produktportfolio
A1: Produktportfolio und Standardisierung
A2: Verändert werden die Wechselwahrscheinlichkeit zwischen zwei Satelliten (v) und der Anpassungsanteil r. Je höher v, desto häufiger folgen unterschiedliche Ausführungen aufeinander. Vergleiche innerhalb eines Blocks die drei Standardisierungsgrade, der Abstand zwischen niedrig und hoch ist die Wirkung der Standardisierung.
A4: Konfiguration | B4: Prüfstationen | C4: Wechselwahrscheinlichkeit v | D4: Standardisierung | E4: Anpassungsanteil r | F4: Programmdauer in ZE | G4: Konfidenzintervall ±
A5: 1 × 30, eine Prüfstation
A6: 1 × 30 | B6: 1 | C6: 0.1 | D6: niedrig | E6: 0.3 | F6: 598.6208 | G6: 9.4028998
A7: 1 × 30 | B7: 1 | C7: 0.1 | D7: mittel | E7: 0.2 | F7: 579.47504 | G7: 7.5960624
A8: 1 × 30 | B8: 1 | C8: 0.1 | D8: hoch | E8: 0.1 | F8: 562.56534 | G8: 6.8344435
A9: 1 × 30 | B9: 1 | C9: 0.3 | D9: niedrig | E9: 0.3 | F9: 643.80525 | G9: 5.6770296
A10: 1 × 30 | B10: 1 | C10: 0.3 | D10: mittel | E10: 0.2 | F10: 607.47979 | G10: 8.7812659
A11: 1 × 30 | B11: 1 | C11: 0.3 | D11: hoch | E11: 0.1 | F11: 579.12658 | G11: 8.0137283
A12: 1 × 30 | B12: 1 | C12: 0.5 | D12: niedrig | E12: 0.3 | F12: 670.42474 | G12: 6.4521995
A13: 1 × 30 | B13: 1 | C13: 0.5 | D13: mittel | E13: 0.2 | F13: 627.5287 | G13: 9.0522131
A14: 1 × 30 | B14: 1 | C14: 0.5 | D14: hoch | E14: 0.1 | F14: 582.89151 | G14: 5.5628041
A15: 1 × 30, drei Prüfstationen
A16: 1 × 30 | B16: 3 | C16: 0.1 | D16: niedrig | E16: 0.3 | F16: 598.43052 | G16: 7.0772411
A17: 1 × 30 | B17: 3 | C17: 0.1 | D17: mittel | E17: 0.2 | F17: 579.73059 | G17: 9.8486515
A18: 1 × 30 | B18: 3 | C18: 0.1 | D18: hoch | E18: 0.1 | F18: 562.93335 | G18: 7.0019404
A19: 1 × 30 | B19: 3 | C19: 0.3 | D19: niedrig | E19: 0.3 | F19: 640.58953 | G19: 7.1410379
A20: 1 × 30 | B20: 3 | C20: 0.3 | D20: mittel | E20: 0.2 | F20: 605.56552 | G20: 7.616869
A21: 1 × 30 | B21: 3 | C21: 0.3 | D21: hoch | E21: 0.1 | F21: 575.29488 | G21: 7.7231518
A22: 1 × 30 | B22: 3 | C22: 0.5 | D22: niedrig | E22: 0.3 | F22: 669.69611 | G22: 10.188018
A23: 1 × 30 | B23: 3 | C23: 0.5 | D23: mittel | E23: 0.2 | F23: 625.45852 | G23: 8.5941783
A24: 1 × 30 | B24: 3 | C24: 0.5 | D24: hoch | E24: 0.1 | F24: 582.91216 | G24: 6.3727528
A25: 5 × 6, eine Prüfstation
A26: 5 × 6 | B26: 1 | C26: 0.1 | D26: niedrig | E26: 0.3 | F26: 506.31604 | G26: 3.1419344
A27: 5 × 6 | B27: 1 | C27: 0.1 | D27: mittel | E27: 0.2 | F27: 506.54314 | G27: 3.610097
A28: 5 × 6 | B28: 1 | C28: 0.1 | D28: hoch | E28: 0.1 | F28: 503.54192 | G28: 3.5350784
A29: 5 × 6 | B29: 1 | C29: 0.3 | D29: niedrig | E29: 0.3 | F29: 526.32918 | G29: 3.5137991
A30: 5 × 6 | B30: 1 | C30: 0.3 | D30: mittel | E30: 0.2 | F30: 510.03954 | G30: 3.0402275
A31: 5 × 6 | B31: 1 | C31: 0.3 | D31: hoch | E31: 0.1 | F31: 503.71523 | G31: 3.1600499
A32: 5 × 6 | B32: 1 | C32: 0.5 | D32: niedrig | E32: 0.3 | F32: 561.52039 | G32: 3.9575475
A33: 5 × 6 | B33: 1 | C33: 0.5 | D33: mittel | E33: 0.2 | F33: 520.47692 | G33: 3.0394916
A34: 5 × 6 | B34: 1 | C34: 0.5 | D34: hoch | E34: 0.1 | F34: 509.39902 | G34: 2.6813145
A35: 5 × 6, drei Prüfstationen
A36: 5 × 6 | B36: 3 | C36: 0.1 | D36: niedrig | E36: 0.3 | F36: 475.409 | G36: 3.7194025
A37: 5 × 6 | B37: 3 | C37: 0.1 | D37: mittel | E37: 0.2 | F37: 463.11222 | G37: 3.6598574
A38: 5 × 6 | B38: 3 | C38: 0.1 | D38: hoch | E38: 0.1 | F38: 452.54331 | G38: 3.882379
A39: 5 × 6 | B39: 3 | C39: 0.3 | D39: niedrig | E39: 0.3 | F39: 528.67801 | G39: 4.1441578
A40: 5 × 6 | B40: 3 | C40: 0.3 | D40: mittel | E40: 0.2 | F40: 492.70238 | G40: 3.4732707
A41: 5 × 6 | B41: 3 | C41: 0.3 | D41: hoch | E41: 0.1 | F41: 466.89867 | G41: 3.8239568
...

Sheet Sensitivitätsanalyse
A1: Sensitivitätsanalyse
A2: Jede Zeile ist ein vollständiger Satz Simulationsläufe mit einer veränderten Annahme. Geprüft wird, ob die vier Befunde B1 bis B4 weiterhin gelten. Die vier Programmdauern sind die Vergleichswerte, aus denen sich die Befunde ergeben. Die Befunde stehen unterhalb der Tabelle.
A4: Veränderte Annahme | B4: Programmdauer 1 × 30 bei einer Prüfstation | C4: Programmdauer 1 × 30 bei drei Prüfstationen | D4: Programmdauer 15 × 2 bei einer Prüfstation | E4: Programmdauer 15 × 2 bei drei Prüfstationen | F4: B1 | G4: B2 | H4: B3 | I4: B4
A5: Referenzfall | B5: 607.47979 | C5: 605.56552 | D5: 491.87127 | E5: 430.81569 | F5: hält | G5: hält | H5: hält | I5: hält
A6: Mindestzeit 0,65 | B6: 574.38777 | C6: 571.61221 | D6: 488.80501 | E6: 411.75061 | F6: hält | G6: hält | H6: hält | I6: hält
A7: Mindestzeit 0,85 | B7: 637.81404 | C7: 625.91326 | D7: 490.58415 | E7: 443.4741 | F7: hält | G7: hält | H7: hält | I7: hält
A8: Streuung CV 0,15 | B8: 575.81391 | C8: 565.46815 | D8: 495.62553 | E8: 404.44741 | F8: hält | G8: hält | H8: hält | I8: hält
A9: Streuung CV 0,45 | B9: 658.89952 | C9: 660.45678 | D9: 494.8612 | E9: 457.17064 | F9: hält | G9: hält | H9: hält | I9: hält
A10: Pruefdauer 1,5 ZE | B10: 602.9723 | C10: 604.50166 | D10: 427.28018 | E10: 427.89469 | F10: hält | G10: hält | H10: hält | I10: hält
A11: Pruefdauer 3,5 ZE | B11: 696.57748 | C11: 606.45183 | D11: 670.76079 | E11: 427.85406 | F11: hält | G11: hält | H11: hält nicht | I11: hält
A13: B1 Die Aufteilung auf mehrere Linien verkürzt die Programmdauer.
A14: B2 Der Gewinn der Aufteilung fällt größer aus, wenn die Prüfkapazität ausreicht.
A15: B3 Bei einer einzelnen langen Linie bringt zusätzliche Prüfkapazität keinen Vorteil.
A16: B4 Standardisierung wirkt vor allem bei häufigen Variantenwechseln.
A18: Einzige Ausnahme ist B3 bei einer Prüfdauer von 3,5 ZE. Dort bindet die Prüfung in jeder Konfiguration, sodass auch die lange Linie von zusätzlicher Prüfkapazität profitiert.

Sheet Verifikation
A1: Verifikation durch Grenzwerttests
A2: Einzelne Einflüsse werden abgeschaltet oder verstärkt. Geprüft wird, ob die Programmdauer in die erwartete Richtung reagiert. Alle Tests in der Konfiguration 5 × 6 mit drei Prüfstationen, je 30 Läufe.
A4: Grenzwerttest | B4: Programmdauer in ZE | C4: erwartete Richtung | D4: Ergebnis
A5: Basislauf | B5: 492.7 | C5: Referenz
A6: ohne Erfahrungseffekt | B6: 541.9 | C6: länger | D6: erfüllt
A7: ohne Mindestzeit | B7: 353.9 | C7: kürzer | D7: erfüllt
A8: ohne Variantenwechsel | B8: 447.4 | C8: kürzer | D8: erfüllt
A9: ohne Streuung | B9: 436.6 | C9: kürzer | D9: erfüllt
A10: volle Fertigungstiefe | B10: 713.8 | C10: länger | D10: erfüllt
A11: ohne Automatisierungsvorteil | B11: 588.4 | C11: länger | D11: erfüllt
A12: eine Prüfstation | B12: 510 | C12: länger | D12: erfüllt
A14: Zusätzlich wird in jedem Lauf geprüft, dass die rechnerischen Untergrenzen von Fertigung und Prüfung nicht unterschritten werden.

Sheet Parameter
A1: Ausprägungen der Modellgrößen
A2: Die gelb hinterlegten Werte bilden den Ausgangsvergleich. Von dort aus verändert jede Versuchsreihe einzelne Größen. Die Herleitung aller Werte steht in Anhang F der Arbeit.
A4: Modellgröße | B4: Ausprägung | C4: Wert im Modell | D4: Bedeutung
A5: Produktportfolio v | B5: niedrig | C5: 0.1 | D5: Wahrscheinlichkeit eines Variantenwechsels je Satellit
A6: Produktportfolio v | B6: Ausgangsvergleich | C6: 0.3
A7: Produktportfolio v | B7: hoch | C7: 0.5
A8: Standardisierung r | B8: niedrig | C8: 0.3 | D8: Anpassungsaufwand je Station als Anteil der Stationszeit
A9: Standardisierung r | B9: Ausgangsvergleich | C9: 0.2 | D9: Mehr Standardisierung bedeutet ein kleineres r
A10: Standardisierung r | B10: hoch | C10: 0.1
A11: Automatisierung k | B11: niedrig | C11: 1 | D11: Faktor auf die reguläre Bearbeitungszeit, 1,0 heißt kein Vorteil
A12: Automatisierung k | B12: Ausgangsvergleich | C12: 0.8
A13: Automatisierung k | B13: hoch | C13: 0.6
A14: Fertigungstiefe f | B14: niedrig | C14: 0.5 | D14: Anteil des intern gefertigten Arbeitsinhalts
A15: Fertigungstiefe f | B15: Ausgangsvergleich | C15: 0.65
A16: Fertigungstiefe f | B16: hoch | C16: 0.8
A17: Prüfstationen K | B17: knapp | C17: 1 | D17: Gemeinsame Prüfung aller Linien, Prüfdauer im Mittel 2,5 ZE
A18: Prüfstationen K | B18: ausreichend | C18: 2
A19: Prüfstationen K | B19: Ausgangsvergleich | C19: 3
A20: Produktionsorganisation | B20: 1 × 30 bis 15 × 2 | D20: Linien mal Stationen je Linie, zusammen stets 30 Stationsplätze
A21: Produktionsorganisation | B21: Ausgangsvergleich | D21: 5 × 6, also fünf Linien mit je sechs Stationen
A23: Programmumfang 180 Satelliten, 30 Stationsplätze, keine Zwischenpuffer, 30 Läufe je Konfiguration. Alle Zeiten sind normierte Zeiteinheiten.
